Workbook

Sheet onboarding_funnel_dataset
A1: user_id | B1: timestamp | C1: event
A2: 5186 | B2: 45292.054 | C2: registration
A3: 1087 | B3: 45292.111 | C3: registration
A4: 6536 | B4: 45292.147 | C4: registration
A5: 3273 | B5: 45292.152 | C5: registration
A6: 7437 | B6: 45292.158 | C6: registration
A7: 467 | B7: 45292.177 | C7: registration
A8: 4490 | B8: 45292.203 | C8: registration
A9: 1967 | B9: 45292.243 | C9: registration
A10: 3419 | B10: 45292.268 | C10: registration
A11: 7246 | B11: 45292.288 | C11: profile_completed
A12: 2169 | B12: 45292.302 | C12: registration
A13: 6275 | B13: 45292.307 | C13: registration
... A12206: 7616 | B12206: 45482.705 | C12206: purchase

Sheet purchases
A1: user_id | B1: timestamp | C1: event | D1: date | E1: week_start | F1: month_start
A2: =IFERROR(__xludf.DUMMYFUNCTION("FILTER(onboarding_funnel_dataset!A:C, onboarding_funnel_dataset!C:C=""purchase"") "),6536.0) -> 6536 | B2: =IFERROR(__xludf.DUMMYFUNCTION("""COMPUTED_VALUE"""),45293.24061342593) -> 45293.241 | C2: =IFERROR(__xludf.DUMMYFUNCTION("""COMPUTED_VALUE"""),"purchase") -> purchase | D2: =INT(VALUE(B2)) -> 45293 | E2: =D2 - WEEKDAY(D2,2) + 1 -> 45292 | F2: =DATE(YEAR(D2),MONTH(D2),1) -> 45292
A3: =IFERROR(__xludf.DUMMYFUNCTION("""COMPUTED_VALUE"""),510.0) -> 510 | B3: =IFERROR(__xludf.DUMMYFUNCTION("""COMPUTED_VALUE"""),45294.13836805556) -> 45294.138 | C3: =IFERROR(__xludf.DUMMYFUNCTION("""COMPUTED_VALUE"""),"purchase") -> purchase | D3: =INT(VALUE(B3)) -> 45294 | E3: =D3 - WEEKDAY(D3,2) + 1 -> 45292 | F3: =DATE(YEAR(D3),MONTH(D3),1) -> 45292
A4: =IFERROR(__xludf.DUMMYFUNCTION("""COMPUTED_VALUE"""),5872.0) -> 5872 | B4: =IFERROR(__xludf.DUMMYFUNCTION("""COMPUTED_VALUE"""),45294.180185185185) -> 45294.18 | C4: =IFERROR(__xludf.DUMMYFUNCTION("""COMPUTED_VALUE"""),"purchase") -> purchase | D4: =INT(VALUE(B4)) -> 45294 | E4: =D4 - WEEKDAY(D4,2) + 1 -> 45292 | F4: =DATE(YEAR(D4),MONTH(D4),1) -> 45292
A5: =IFERROR(__xludf.DUMMYFUNCTION("""COMPUTED_VALUE"""),6275.0) -> 6275 | B5: =IFERROR(__xludf.DUMMYFUNCTION("""COMPUTED_VALUE"""),45294.66270833334) -> 45294.663 | C5: =IFERROR(__xludf.DUMMYFUNCTION("""COMPUTED_VALUE"""),"purchase") -> purchase | D5: =INT(VALUE(B5)) -> 45294 | E5: =D5 - WEEKDAY(D5,2) + 1 -> 45292 | F5: =DATE(YEAR(D5),MONTH(D5),1) -> 45292
A6: =IFERROR(__xludf.DUMMYFUNCTION("""COMPUTED_VALUE"""),1374.0) -> 1374 | B6: =IFERROR(__xludf.DUMMYFUNCTION("""COMPUTED_VALUE"""),45295.11927083333) -> 45295.119 | C6: =IFERROR(__xludf.DUMMYFUNCTION("""COMPUTED_VALUE"""),"purchase") -> purchase | D6: =INT(VALUE(B6)) -> 45295 | E6: =D6 - WEEKDAY(D6,2) + 1 -> 45292 | F6: =DATE(YEAR(D6),MONTH(D6),1) -> 45292
A7: =IFERROR(__xludf.DUMMYFUNCTION("""COMPUTED_VALUE"""),504.0) -> 504 | B7: =IFERROR(__xludf.DUMMYFUNCTION("""COMPUTED_VALUE"""),45295.2700462963) -> 45295.27 | C7: =IFERROR(__xludf.DUMMYFUNCTION("""COMPUTED_VALUE"""),"purchase") -> purchase | D7: =INT(VALUE(B7)) -> 45295 | E7: =D7 - WEEKDAY(D7,2) + 1 -> 45292 | F7: =DATE(YEAR(D7),MONTH(D7),1) -> 45292
A8: =IFERROR(__xludf.DUMMYFUNCTION("""COMPUTED_VALUE"""),1314.0) -> 1314 | B8: =IFERROR(__xludf.DUMMYFUNCTION("""COMPUTED_VALUE"""),45295.321851851855) -> 45295.322 | C8: =IFERROR(__xludf.DUMMYFUNCTION("""COMPUTED_VALUE"""),"purchase") -> purchase | D8: =INT(VALUE(B8)) -> 45295 | E8: =D8 - WEEKDAY(D8,2) + 1 -> 45292 | F8: =DATE(YEAR(D8),MONTH(D8),1) -> 45292
A9: =IFERROR(__xludf.DUMMYFUNCTION("""COMPUTED_VALUE"""),5888.0) -> 5888 | B9: =IFERROR(__xludf.DUMMYFUNCTION("""COMPUTED_VALUE"""),45295.34295138889) -> 45295.343 | C9: =IFERROR(__xludf.DUMMYFUNCTION("""COMPUTED_VALUE"""),"purchase") -> purchase | D9: =INT(VALUE(B9)) -> 45295 | E9: =D9 - WEEKDAY(D9,2) + 1 -> 45292 | F9: =DATE(YEAR(D9),MONTH(D9),1) -> 45292
A10: =IFERROR(__xludf.DUMMYFUNCTION("""COMPUTED_VALUE"""),1704.0) -> 1704 | B10: =IFERROR(__xludf.DUMMYFUNCTION("""COMPUTED_VALUE"""),45295.46834490741) -> 45295.468 | C10: =IFERROR(__xludf.DUMMYFUNCTION("""COMPUTED_VALUE"""),"purchase") -> purchase | D10: =INT(VALUE(B10)) -> 45295 | E10: =D10 - WEEKDAY(D10,2) + 1 -> 45292 | F10: =DATE(YEAR(D10),MONTH(D10),1) -> 45292
A11: =IFERROR(__xludf.DUMMYFUNCTION("""COMPUTED_VALUE"""),3575.0) -> 3575 | B11: =IFERROR(__xludf.DUMMYFUNCTION("""COMPUTED_VALUE"""),45295.58864583333) -> 45295.589 | C11: =IFERROR(__xludf.DUMMYFUNCTION("""COMPUTED_VALUE"""),"purchase") -> purchase | D11: =INT(VALUE(B11)) -> 45295 | E11: =D11 - WEEKDAY(D11,2) + 1 -> 45292 | F11: =DATE(YEAR(D11),MONTH(D11),1) -> 45292
A12: =IFERROR(__xludf.DUMMYFUNCTION("""COMPUTED_VALUE"""),5565.0) -> 5565 | B12: =IFERROR(__xludf.DUMMYFUNCTION("""COMPUTED_VALUE"""),45295.871458333335) -> 45295.871 | C12: =IFERROR(__xludf.DUMMYFUNCTION("""COMPUTED_VALUE"""),"purchase") -> purchase | D12: =INT(VALUE(B12)) -> 45295 | E12: =D12 - WEEKDAY(D12,2) + 1 -> 45292 | F12: =DATE(YEAR(D12),MONTH(D12),1) -> 45292
A13: =IFERROR(__xludf.DUMMYFUNCTION("""COMPUTED_VALUE"""),211.0) -> 211 | B13: =IFERROR(__xludf.DUMMYFUNCTION("""COMPUTED_VALUE"""),45295.93908564815) -> 45295.939 | C13: =IFERROR(__xludf.DUMMYFUNCTION("""COMPUTED_VALUE"""),"purchase") -> purchase | D13: =INT(VALUE(B13)) -> 45295 | E13: =D13 - WEEKDAY(D13,2) + 1 -> 45292 | F13: =DATE(YEAR(D13),MONTH(D13),1) -> 45292
A14: =IFERROR(__xludf.DUMMYFUNCTION("""COMPUTED_VALUE"""),1738.0) -> 1738 | B14: =IFERROR(__xludf.DUMMYFUNCTION("""COMPUTED_VALUE"""),45296.05336805555) -> 45296.053 | C14: =IFERROR(__xludf.DUMMYFUNCTION("""COMPUTED_VALUE"""),"purchase") -> purchase | D14: =INT(VALUE(B14)) -> 45296 | E14: =D14 - WEEKDAY(D14,2) + 1 -> 45292 | F14: =DATE(YEAR(D14),MONTH(D14),1) -> 45292
A15: =IFERROR(__xludf.DUMMYFUNCTION("""COMPUTED_VALUE"""),6522.0) -> 6522 | B15: =IFERROR(__xludf.DUMMYFUNCTION("""COMPUTED_VALUE"""),45296.08513888889) -> 45296.085 | C15: =IFERROR(__xludf.DUMMYFUNCTION("""COMPUTED_VALUE"""),"purchase") -> purchase | D15: =INT(VALUE(B15)) -> 45296 | E15: =D15 - WEEKDAY(D15,2) + 1 -> 45292 | F15: =DATE(YEAR(D15),MONTH(D15),1) -> 45292
A16: =IFERROR(__xludf.DUMMYFUNCTION("""COMPUTED_VALUE"""),7602.0) -> 7602 | B16: =IFERROR(__xludf.DUMMYFUNCTION("""COMPUTED_VALUE"""),45296.33263888889) -> 45296.333 | C16: =IFERROR(__xludf.DUMMYFUNCTION("""COMPUTED_VALUE"""),"purchase") -> purchase | D16: =INT(VALUE(B16)) -> 45296 | E16: =D16 - WEEKDAY(D16,2) + 1 -> 45292 | F16: =DATE(YEAR(D16),MONTH(D16),1) -> 45292
A17: =IFERROR(__xludf.DUMMYFUNCTION("""COMPUTED_VALUE"""),7811.0) -> 7811 | B17: =IFERROR(__xludf.DUMMYFUNCTION("""COMPUTED_VALUE"""),45296.37855324074) -> 45296.379 | C17: =IFERROR(__xludf.DUMMYFUNCTION("""COMPUTED_VALUE"""),"purchase") -> purchase | D17: =INT(VALUE(B17)) -> 45296 | E17: =D17 - WEEKDAY(D17,2) + 1 -> 45292 | F17: =DATE(YEAR(D17),MONTH(D17),1) -> 45292
A18: =IFERROR(__xludf.DUMMYFUNCTION("""COMPUTED_VALUE"""),4490.0) -> 4490 | B18: =IFERROR(__xludf.DUMMYFUNCTION("""COMPUTED_VALUE"""),45296.433275462965) -> 45296.433 | C18: =IFERROR(__xludf.DUMMYFUNCTION("""COMPUTED_VALUE"""),"purchase") -> purchase | D18: =INT(VALUE(B18)) -> 45296 | E18: =D18 - WEEKDAY(D18,2) + 1 -> 45292 | F18: =DATE(YEAR(D18),MONTH(D18),1) -> 45292
A19: =IFERROR(__xludf.DUMMYFUNCTION("""COMPUTED_VALUE"""),3255.0) -> 3255 | B19: =IFERROR(__xludf.DUMMYFUNCTION("""COMPUTED_VALUE"""),45296.73064814815) -> 45296.731 | C19: =IFERROR(__xludf.DUMMYFUNCTION("""COMPUTED_VALUE"""),"purchase") -> purchase | D19: =INT(VALUE(B19)) -> 45296 | E19: =D19 - WEEKDAY(D19,2) + 1 -> 45292 | F19: =DATE(YEAR(D19),MONTH(D19),1) -> 45292
A20: =IFERROR(__xludf.DUMMYFUNCTION("""COMPUTED_VALUE"""),5147.0) -> 5147 | B20: =IFERROR(__xludf.DUMMYFUNCTION("""COMPUTED_VALUE"""),45296.81914351852) -> 45296.819 | C20: =IFERROR(__xludf.DUMMYFUNCTION("""COMPUTED_VALUE"""),"purchase") -> purchase | D20: =INT(VALUE(B20)) -> 45296 | E20: =D20 - WEEKDAY(D20,2) + 1 -> 45292 | F20: =DATE(YEAR(D20),MONTH(D20),1) -> 45292
A21: =IFERROR(__xludf.DUMMYFUNCTION("""COMPUTED_VALUE"""),4032.0) -> 4032 | B21: =IFERROR(__xludf.DUMMYFUNCTION("""COMPUTED_VALUE"""),45296.96246527778) -> 45296.962 | C21: =IFERROR(__xludf.DUMMYFUNCTION("""COMPUTED_VALUE"""),"purchase") -> purchase | D21: =INT(VALUE(B21)) -> 45296 | E21: =D21 - WEEKDAY(D21,2) + 1 -> 45292 | F21: =DATE(YEAR(D21),MONTH(D21),1) -> 45292
A22: =IFERROR(__xludf.DUMMYFUNCTION("""COMPUTED_VALUE"""),3218.0) -> 3218 | B22: =IFERROR(__xludf.DUMMYFUNCTION("""COMPUTED_VALUE"""),45297.22310185185) -> 45297.223 | C22: =IFERROR(__xludf.DUMMYFUNCTION("""COMPUTED_VALUE"""),"purchase") -> purchase | D22: =INT(VALUE(B22)) -> 45297 | E22: =D22 - WEEKDAY(D22,2) + 1 -> 45292 | F22: =DATE(YEAR(D22),MONTH(D22),1) -> 45292
A23: =IFERROR(__xludf.DUMMYFUNCTION("""COMPUTED_VALUE"""),4776.0) -> 4776 | B23: =IFERROR(__xludf.DUMMYFUNCTION("""COMPUTED_VALUE"""),45297.27302083333) -> 45297.273 | C23: =IFERROR(__xludf.DUMMYFUNCTION("""COMPUTED_VALUE"""),"purchase") -> purchase | D23: =INT(VALUE(B23)) -> 45297 | E23: =D23 - WEEKDAY(D23,2) + 1 -> 45292 | F23: =DATE(YEAR(D23),MONTH(D23),1) -> 45292
A24: =IFERROR(__xludf.DUMMYFUNCTION("""COMPUTED_VALUE"""),5781.0) -> 5781 | B24: =IFERROR(__xludf.DUMMYFUNCTION("""COMPUTED_VALUE"""),45297.37517361111) -> 45297.375 | C24: =IFERROR(__xludf.DUMMYFUNCTION("""COMPUTED_VALUE"""),"purchase") -> purchase | D24: =INT(VALUE(B24)) -> 45297 | E24: =D24 - WEEKDAY(D24,2) + 1 -> 45292 | F24: =DATE(YEAR(D24),MONTH(D24),1) -> 45292
A25: =IFERROR(__xludf.DUMMYFUNCTION("""COMPUTED_VALUE"""),7489.0) -> 7489 | B25: =IFERROR(__xludf.DUMMYFUNCTION("""COMPUTED_VALUE"""),45297.51167824074) -> 45297.512 | C25: =IFERROR(__xludf.DUMMYFUNCTION("""COMPUTED_VALUE"""),"purchase") -> purchase | D25: =INT(VALUE(B25)) -> 45297 | E25: =D25 - WEEKDAY(D25,2) + 1 -> 45292 | F25: =DATE(YEAR(D25),MONTH(D25),1) -> 45292
A26: =IFERROR(__xludf.DUMMYFUNCTION("""COMPUTED_VALUE"""),6460.0) -> 6460 | B26: =IFERROR(__xludf.DUMMYFUNCTION("""COMPUTED_VALUE"""),45297.697488425925) -> 45297.697 | C26: =IFERROR(__xludf.DUMMYFUNCTION("""COMPUTED_VALUE"""),"purchase") -> purchase | D26: =INT(VALUE(B26)) -> 45297 | E26: =D26 - WEEKDAY(D26,2) + 1 -> 45292 | F26: =DATE(YEAR(D26),MONTH(D26),1) -> 45292
A27: =IFERROR(__xludf.DUMMYFUNCTION("""COMPUTED_VALUE"""),6612.0) -> 6612 | B27: =IFERROR(__xludf.DUMMYFUNCTION("""COMPUTED_VALUE"""),45297.716365740744) -> 45297.716 | C27: =IFERROR(__xludf.DUMMYFUNCTION("""COMPUTED_VALUE"""),"purchase") -> purchase | D27: =INT(VALUE(B27)) -> 45297 | E27: =D27 - WEEKDAY(D27,2) + 1 -> 45292 | F27: =DATE(YEAR(D27),MONTH(D27),1) -> 45292
A28: =IFERROR(__xludf.DUMMYFUNCTION("""COMPUTED_VALUE"""),7822.0) -> 7822 | B28: =IFERROR(__xludf.DUMMYFUNCTION("""COMPUTED_VALUE"""),45298.27206018518) -> 45298.272 | C28: =IFERROR(__xludf.DUMMYFUNCTION("""COMPUTED_VALUE"""),"purchase") -> purchase | D28: =INT(VALUE(B28)) -> 45298 | E28: =D28 - WEEKDAY(D28,2) + 1 -> 45292 | F28: =DATE(YEAR(D28),MONTH(D28),1) -> 45292
A29: =IFERROR(__xludf.DUMMYFUNCTION("""COMPUTED_VALUE"""),3533.0) -> 3533 | B29: =IFERROR(__xludf.DUMMYFUNCTION("""COMPUTED_VALUE"""),45298.31894675926) -> 45298.319 | C29: =IFERROR(__xludf.DUMMYFUNCTION("""COMPUTED_VALUE"""),"purchase") -> purchase | D29: =INT(VALUE(B29)) -> 45298 | E29: =D29 - WEEKDAY(D29,2) + 1 -> 45292 | F29: =DATE(YEAR(D29),MONTH(D29),1) -> 45292
A30: =IFERROR(__xludf.DUMMYFUNCTION("""COMPUTED_VALUE"""),3419.0) -> 3419 | B30: =IFERROR(__xludf.DUMMYFUNCTION("""COMPUTED_VALUE"""),45298.7319212963) -> 45298.732 | C30: =IFERROR(__xludf.DUMMYFUNCTION("""COMPUTED_VALUE"""),"purchase") -> purchase | D30: =INT(VALUE(B30)) -> 45298 | E30: =D30 - WEEKDAY(D30,2) + 1 -> 45292 | F30: =DATE(YEAR(D30),MONTH(D30),1) -> 45292
A31: =IFERROR(__xludf.DUMMYFUNCTION("""COMPUTED_VALUE"""),5194.0) -> 5194 | B31: =IFERROR(__xludf.DUMMYFUNCTION("""COMPUTED_VALUE"""),45298.848449074074) -> 45298.848 | C31: =IFERROR(__xludf.DUMMYFUNCTION("""COMPUTED_VALUE"""),"purchase") -> purchase | D31: =INT(VALUE(B31)) -> 45298 | E31: =D31 - WEEKDAY(D31,2) + 1 -> 45292 | F31: =DATE(YEAR(D31),MONTH(D31),1) -> 45292
A32: =IFERROR(__xludf.DUMMYFUNCTION("""COMPUTED_VALUE"""),7003.0) -> 7003 | B32: =IFERROR(__xludf.DUMMYFUNCTION("""COMPUTED_VALUE"""),45298.95291666667) -> 45298.953 | C32: =IFERROR(__xludf.DUMMYFUNCTION("""COMPUTED_VALUE"""),"purchase") -> purchase | D32: =INT(VALUE(B32)) -> 45298 | E32: =D32 - WEEKDAY(D32,2) + 1 -> 45292 | F32: =DATE(YEAR(D32),MONTH(D32),1) -> 45292
A33: =IFERROR(__xludf.DUMMYFUNCTION("""COMPUTED_VALUE"""),2405.0) -> 2405 | B33: =IFERROR(__xludf.DUMMYFUNCTION("""COMPUTED_VALUE"""),45299.128530092596) -> 45299.129 | C33: =IFERROR(__xludf.DUMMYFUNCTION("""COMPUTED_VALUE"""),"purchase") -> purchase | D33: =INT(VALUE(B33)) -> 45299 | E33: =D33 - WEEKDAY(D33,2) + 1 -> 45299 | F33: =DATE(YEAR(D33),MONTH(D33),1) -> 45292
A34: =IFERROR(__xludf.DUMMYFUNCTION("""COMPUTED_VALUE"""),765.0) -> 765 | B34: =IFERROR(__xludf.DUMMYFUNCTION("""COMPUTED_VALUE"""),45299.14980324074) -> 45299.15 | C34: =IFERROR(__xludf.DUMMYFUNCTION("""COMPUTED_VALUE"""),"purchase") -> purchase | D34: =INT(VALUE(B34)) -> 45299 | E34: =D34 - WEEKDAY(D34,2) + 1 -> 45299 | F34: =DATE(YEAR(D34),MONTH(D34),1) -> 45292
A35: =IFERROR(__xludf.DUMMYFUNCTION("""COMPUTED_VALUE"""),2993.0) -> 2993 | B35: =IFERROR(__xludf.DUMMYFUNCTION("""COMPUTED_VALUE"""),45299.26960648148) -> 45299.27 | C35: =IFERROR(__xludf.DUMMYFUNCTION("""COMPUTED_VALUE"""),"purchase") -> purchase | D35: =INT(VALUE(B35)) -> 45299 | E35: =D35 - WEEKDAY(D35,2) + 1 -> 45299 | F35: =DATE(YEAR(D35),MONTH(D35),1) -> 45292
A36: =IFERROR(__xludf.DUMMYFUNCTION("""COMPUTED_VALUE"""),4363.0) -> 4363 | B36: =IFERROR(__xludf.DUMMYFUNCTION("""COMPUTED_VALUE"""),45299.28465277778) -> 45299.285 | C36: =IFERROR(__xludf.DUMMYFUNCTION("""COMPUTED_VALUE"""),"purchase") -> purchase | D36: =INT(VALUE(B36)) -> 45299 | E36: =D36 - WEEKDAY(D36,2) + 1 -> 45299 | F36: =DATE(YEAR(D36),MONTH(D36),1) -> 45292
A37: =IFERROR(__xludf.DUMMYFUNCTION("""COMPUTED_VALUE"""),7467.0) -> 7467 | B37: =IFERROR(__xludf.DUMMYFUNCTION("""COMPUTED_VALUE"""),45299.60071759259) -> 45299.601 | C37: =IFERROR(__xludf.DUMMYFUNCTION("""COMPUTED_VALUE"""),"purchase") -> purchase | D37: =INT(VALUE(B37)) -> 45299 | E37: =D37 - WEEKDAY(D37,2) + 1 -> 45299 | F37: =DATE(YEAR(D37),MONTH(D37),1) -> 45292
A38: =IFERROR(__xludf.DUMMYFUNCTION("""COMPUTED_VALUE"""),4592.0) -> 4592 | B38: =IFERROR(__xludf.DUMMYFUNCTION("""COMPUTED_VALUE"""),45299.70141203704) -> 45299.701 | C38: =IFERROR(__xludf.DUMMYFUNCTION("""COMPUTED_VALUE"""),"purchase") -> purchase | D38: =INT(VALUE(B38)) -> 45299 | E38: =D38 - WEEKDAY(D38,2) + 1 -> 45299 | F38: =DATE(YEAR(D38),MONTH(D38),1) -> 45292
A39: =IFERROR(__xludf.DUMMYFUNCTION("""COMPUTED_VALUE"""),4321.0) -> 4321 | B39: =IFERROR(__xludf.DUMMYFUNCTION("""COMPUTED_VALUE"""),45299.791550925926) -> 45299.792 | C39: =IFERROR(__xludf.DUMMYFUNCTION("""COMPUTED_VALUE"""),"purchase") -> purchase | D39: =INT(VALUE(B39)) -> 45299 | E39: =D39 - WEEKDAY(D39,2) + 1 -> 45299 | F39: =DATE(YEAR(D39),MONTH(D39),1) -> 45292
A40: =IFERROR(__xludf.DUMMYFUNCTION("""COMPUTED_VALUE"""),5186.0) -> 5186 | B40: =IFERROR(__xludf.DUMMYFUNCTION("""COMPUTED_VALUE"""),45299.83324074074) -> 45299.833 | C40: =IFERROR(__xludf.DUMMYFUNCTION("""COMPUTED_VALUE"""),"purchase") -> purchase | D40: =INT(VALUE(B40)) -> 45299 | E40: =D40 - WEEKDAY(D40,2) + 1 -> 45299 | F40: =DATE(YEAR(D40),MONTH(D40),1) -> 45292
...

Sheet dau
A1: Date | B1: DAU | C1: Month_start
A2: {=SORT(UNIQUE(purchases!D2:D1001))} -> 45293 | B2: =IFERROR(__xludf.DUMMYFUNCTION("COUNTUNIQUE(FILTER(purchases!$A$2:$A1001, purchases!$D$2:$D1001=A2))"),1.0) -> 1 | C2: =VLOOKUP(A2, purchases!$D$2:$F1001, 3, FALSE) -> 45292
A3: 45294 | B3: =IFERROR(__xludf.DUMMYFUNCTION("COUNTUNIQUE(FILTER(purchases!$A$2:$A1001, purchases!$D$2:$D1001=A3))"),3.0) -> 3 | C3: =VLOOKUP(A3, purchases!$D$2:$F1001, 3, FALSE) -> 45292
A4: 45295 | B4: =IFERROR(__xludf.DUMMYFUNCTION("COUNTUNIQUE(FILTER(purchases!$A$2:$A1001, purchases!$D$2:$D1001=A4))"),8.0) -> 8 | C4: =VLOOKUP(A4, purchases!$D$2:$F1001, 3, FALSE) -> 45292
A5: 45296 | B5: =IFERROR(__xludf.DUMMYFUNCTION("COUNTUNIQUE(FILTER(purchases!$A$2:$A1001, purchases!$D$2:$D1001=A5))"),8.0) -> 8 | C5: =VLOOKUP(A5, purchases!$D$2:$F1001, 3, FALSE) -> 45292
A6: 45297 | B6: =IFERROR(__xludf.DUMMYFUNCTION("COUNTUNIQUE(FILTER(purchases!$A$2:$A1001, purchases!$D$2:$D1001=A6))"),6.0) -> 6 | C6: =VLOOKUP(A6, purchases!$D$2:$F1001, 3, FALSE) -> 45292
A7: 45298 | B7: =IFERROR(__xludf.DUMMYFUNCTION("COUNTUNIQUE(FILTER(purchases!$A$2:$A1001, purchases!$D$2:$D1001=A7))"),5.0) -> 5 | C7: =VLOOKUP(A7, purchases!$D$2:$F1001, 3, FALSE) -> 45292
A8: 45299 | B8: =IFERROR(__xludf.DUMMYFUNCTION("COUNTUNIQUE(FILTER(purchases!$A$2:$A1001, purchases!$D$2:$D1001=A8))"),8.0) -> 8 | C8: =VLOOKUP(A8, purchases!$D$2:$F1001, 3, FALSE) -> 45292
A9: 45300 | B9: =IFERROR(__xludf.DUMMYFUNCTION("COUNTUNIQUE(FILTER(purchases!$A$2:$A1001, purchases!$D$2:$D1001=A9))"),5.0) -> 5 | C9: =VLOOKUP(A9, purchases!$D$2:$F1001, 3, FALSE) -> 45292
A10: 45301 | B10: =IFERROR(__xludf.DUMMYFUNCTION("COUNTUNIQUE(FILTER(purchases!$A$2:$A1001, purchases!$D$2:$D1001=A10))"),16.0) -> 16 | C10: =VLOOKUP(A10, purchases!$D$2:$F1001, 3, FALSE) -> 45292
A11: 45302 | B11: =IFERROR(__xludf.DUMMYFUNCTION("COUNTUNIQUE(FILTER(purchases!$A$2:$A1001, purchases!$D$2:$D1001=A11))"),13.0) -> 13 | C11: =VLOOKUP(A11, purchases!$D$2:$F1001, 3, FALSE) -> 45292
A12: 45303 | B12: =IFERROR(__xludf.DUMMYFUNCTION("COUNTUNIQUE(FILTER(purchases!$A$2:$A1001, purchases!$D$2:$D1001=A12))"),11.0) -> 11 | C12: =VLOOKUP(A12, purchases!$D$2:$F1001, 3, FALSE) -> 45292
A13: 45304 | B13: =IFERROR(__xludf.DUMMYFUNCTION("COUNTUNIQUE(FILTER(purchases!$A$2:$A1001, purchases!$D$2:$D1001=A13))"),13.0) -> 13 | C13: =VLOOKUP(A13, purchases!$D$2:$F1001, 3, FALSE) -> 45292
A14: 45305 | B14: =IFERROR(__xludf.DUMMYFUNCTION("COUNTUNIQUE(FILTER(purchases!$A$2:$A1001, purchases!$D$2:$D1001=A14))"),9.0) -> 9 | C14: =VLOOKUP(A14, purchases!$D$2:$F1001, 3, FALSE) -> 45292
A15: 45306 | B15: =IFERROR(__xludf.DUMMYFUNCTION("COUNTUNIQUE(FILTER(purchases!$A$2:$A1001, purchases!$D$2:$D1001=A15))"),12.0) -> 12 | C15: =VLOOKUP(A15, purchases!$D$2:$F1001, 3, FALSE) -> 45292
A16: 45307 | B16: =IFERROR(__xludf.DUMMYFUNCTION("COUNTUNIQUE(FILTER(purchases!$A$2:$A1001, purchases!$D$2:$D1001=A16))"),16.0) -> 16 | C16: =VLOOKUP(A16, purchases!$D$2:$F1001, 3, FALSE) -> 45292
A17: 45308 | B17: =IFERROR(__xludf.DUMMYFUNCTION("COUNTUNIQUE(FILTER(purchases!$A$2:$A1001, purchases!$D$2:$D1001=A17))"),15.0) -> 15 | C17: =VLOOKUP(A17, purchases!$D$2:$F1001, 3, FALSE) -> 45292
A18: 45309 | B18: =IFERROR(__xludf.DUMMYFUNCTION("COUNTUNIQUE(FILTER(purchases!$A$2:$A1001, purchases!$D$2:$D1001=A18))"),10.0) -> 10 | C18: =VLOOKUP(A18, purchases!$D$2:$F1001, 3, FALSE) -> 45292
A19: 45310 | B19: =IFERROR(__xludf.DUMMYFUNCTION("COUNTUNIQUE(FILTER(purchases!$A$2:$A1001, purchases!$D$2:$D1001=A19))"),12.0) -> 12 | C19: =VLOOKUP(A19, purchases!$D$2:$F1001, 3, FALSE) -> 45292
A20: 45311 | B20: =IFERROR(__xludf.DUMMYFUNCTION("COUNTUNIQUE(FILTER(purchases!$A$2:$A1001, purchases!$D$2:$D1001=A20))"),13.0) -> 13 | C20: =VLOOKUP(A20, purchases!$D$2:$F1001, 3, FALSE) -> 45292
A21: 45312 | B21: =IFERROR(__xludf.DUMMYFUNCTION("COUNTUNIQUE(FILTER(purchases!$A$2:$A1001, purchases!$D$2:$D1001=A21))"),6.0) -> 6 | C21: =VLOOKUP(A21, purchases!$D$2:$F1001, 3, FALSE) -> 45292
A22: 45313 | B22: =IFERROR(__xludf.DUMMYFUNCTION("COUNTUNIQUE(FILTER(purchases!$A$2:$A1001, purchases!$D$2:$D1001=A22))"),13.0) -> 13 | C22: =VLOOKUP(A22, purchases!$D$2:$F1001, 3, FALSE) -> 45292
A23: 45314 | B23: =IFERROR(__xludf.DUMMYFUNCTION("COUNTUNIQUE(FILTER(purchases!$A$2:$A1001, purchases!$D$2:$D1001=A23))"),8.0) -> 8 | C23: =VLOOKUP(A23, purchases!$D$2:$F1001, 3, FALSE) -> 45292
A24: 45315 | B24: =IFERROR(__xludf.DUMMYFUNCTION("COUNTUNIQUE(FILTER(purchases!$A$2:$A1001, purchases!$D$2:$D1001=A24))"),12.0) -> 12 | C24: =VLOOKUP(A24, purchases!$D$2:$F1001, 3, FALSE) -> 45292
A25: 45316 | B25: =IFERROR(__xludf.DUMMYFUNCTION("COUNTUNIQUE(FILTER(purchases!$A$2:$A1001, purchases!$D$2:$D1001=A25))"),12.0) -> 12 | C25: =VLOOKUP(A25, purchases!$D$2:$F1001, 3, FALSE) -> 45292
A26: 45317 | B26: =IFERROR(__xludf.DUMMYFUNCTION("COUNTUNIQUE(FILTER(purchases!$A$2:$A1001, purchases!$D$2:$D1001=A26))"),14.0) -> 14 | C26: =VLOOKUP(A26, purchases!$D$2:$F1001, 3, FALSE) -> 45292
A27: 45318 | B27: =IFERROR(__xludf.DUMMYFUNCTION("COUNTUNIQUE(FILTER(purchases!$A$2:$A1001, purchases!$D$2:$D1001=A27))"),10.0) -> 10 | C27: =VLOOKUP(A27, purchases!$D$2:$F1001, 3, FALSE) -> 45292
A28: 45319 | B28: =IFERROR(__xludf.DUMMYFUNCTION("COUNTUNIQUE(FILTER(purchases!$A$2:$A1001, purchases!$D$2:$D1001=A28))"),4.0) -> 4 | C28: =VLOOKUP(A28, purchases!$D$2:$F1001, 3, FALSE) -> 45292
A29: 45320 | B29: =IFERROR(__xludf.DUMMYFUNCTION("COUNTUNIQUE(FILTER(purchases!$A$2:$A1001, purchases!$D$2:$D1001=A29))"),21.0) -> 21 | C29: =VLOOKUP(A29, purchases!$D$2:$F1001, 3, FALSE) -> 45292
A30: 45321 | B30: =IFERROR(__xludf.DUMMYFUNCTION("COUNTUNIQUE(FILTER(purchases!$A$2:$A1001, purchases!$D$2:$D1001=A30))"),7.0) -> 7 | C30: =VLOOKUP(A30, purchases!$D$2:$F1001, 3, FALSE) -> 45292
A31: 45322 | B31: =IFERROR(__xludf.DUMMYFUNCTION("COUNTUNIQUE(FILTER(purchases!$A$2:$A1001, purchases!$D$2:$D1001=A31))"),4.0) -> 4 | C31: =VLOOKUP(A31, purchases!$D$2:$F1001, 3, FALSE) -> 45292
A32: 45323 | B32: =IFERROR(__xludf.DUMMYFUNCTION("COUNTUNIQUE(FILTER(purchases!$A$2:$A1001, purchases!$D$2:$D1001=A32))"),11.0) -> 11 | C32: =VLOOKUP(A32, purchases!$D$2:$F1001, 3, FALSE) -> 45323
A33: 45324 | B33: =IFERROR(__xludf.DUMMYFUNCTION("COUNTUNIQUE(FILTER(purchases!$A$2:$A1001, purchases!$D$2:$D1001=A33))"),11.0) -> 11 | C33: =VLOOKUP(A33, purchases!$D$2:$F1001, 3, FALSE) -> 45323
A34: 45325 | B34: =IFERROR(__xludf.DUMMYFUNCTION("COUNTUNIQUE(FILTER(purchases!$A$2:$A1001, purchases!$D$2:$D1001=A34))"),12.0) -> 12 | C34: =VLOOKUP(A34, purchases!$D$2:$F1001, 3, FALSE) -> 45323
A35: 45326 | B35: =IFERROR(__xludf.DUMMYFUNCTION("COUNTUNIQUE(FILTER(purchases!$A$2:$A1001, purchases!$D$2:$D1001=A35))"),13.0) -> 13 | C35: =VLOOKUP(A35, purchases!$D$2:$F1001, 3, FALSE) -> 45323
A36: 45327 | B36: =IFERROR(__xludf.DUMMYFUNCTION("COUNTUNIQUE(FILTER(purchases!$A$2:$A1001, purchases!$D$2:$D1001=A36))"),14.0) -> 14 | C36: =VLOOKUP(A36, purchases!$D$2:$F1001, 3, FALSE) -> 45323
A37: 45328 | B37: =IFERROR(__xludf.DUMMYFUNCTION("COUNTUNIQUE(FILTER(purchases!$A$2:$A1001, purchases!$D$2:$D1001=A37))"),10.0) -> 10 | C37: =VLOOKUP(A37, purchases!$D$2:$F1001, 3, FALSE) -> 45323
A38: 45329 | B38: =IFERROR(__xludf.DUMMYFUNCTION("COUNTUNIQUE(FILTER(purchases!$A$2:$A1001, purchases!$D$2:$D1001=A38))"),19.0) -> 19 | C38: =VLOOKUP(A38, purchases!$D$2:$F1001, 3, FALSE) -> 45323
A39: 45330 | B39: =IFERROR(__xludf.DUMMYFUNCTION("COUNTUNIQUE(FILTER(purchases!$A$2:$A1001, purchases!$D$2:$D1001=A39))"),7.0) -> 7 | C39: =VLOOKUP(A39, purchases!$D$2:$F1001, 3, FALSE) -> 45323
A40: 45331 | B40: =IFERROR(__xludf.DUMMYFUNCTION("COUNTUNIQUE(FILTER(purchases!$A$2:$A1001, purchases!$D$2:$D1001=A40))"),9.0) -> 9 | C40: =VLOOKUP(A40, purchases!$D$2:$F1001, 3, FALSE) -> 45323
...

Sheet wau
A1: Week | B1: WAU | C1: Month_start
A2: {=SORT(UNIQUE(purchases!E2:E1000))} -> 45292 | B2: =IFERROR(__xludf.DUMMYFUNCTION("COUNTUNIQUE(FILTER(purchases!$A$2:$A1000, purchases!$E$2:$E1000=A2))"),31.0) -> 31 | C2: {=XLOOKUP(A2, purchases!$E$2:$E1000, purchases!$F$2:$F1000)} -> 45292
A3: 45299 | B3: =IFERROR(__xludf.DUMMYFUNCTION("COUNTUNIQUE(FILTER(purchases!$A$2:$A1000, purchases!$E$2:$E1000=A3))"),75.0) -> 75 | C3: {=XLOOKUP(A3, purchases!$E$2:$E1000, purchases!$F$2:$F1000)} -> 45292
A4: 45306 | B4: =IFERROR(__xludf.DUMMYFUNCTION("COUNTUNIQUE(FILTER(purchases!$A$2:$A1000, purchases!$E$2:$E1000=A4))"),84.0) -> 84 | C4: {=XLOOKUP(A4, purchases!$E$2:$E1000, purchases!$F$2:$F1000)} -> 45292
A5: 45313 | B5: =IFERROR(__xludf.DUMMYFUNCTION("COUNTUNIQUE(FILTER(purchases!$A$2:$A1000, purchases!$E$2:$E1000=A5))"),73.0) -> 73 | C5: {=XLOOKUP(A5, purchases!$E$2:$E1000, purchases!$F$2:$F1000)} -> 45292
A6: 45320 | B6: =IFERROR(__xludf.DUMMYFUNCTION("COUNTUNIQUE(FILTER(purchases!$A$2:$A1000, purchases!$E$2:$E1000=A6))"),79.0) -> 79 | C6: {=XLOOKUP(A6, purchases!$E$2:$E1000, purchases!$F$2:$F1000)} -> 45292
A7: 45327 | B7: =IFERROR(__xludf.DUMMYFUNCTION("COUNTUNIQUE(FILTER(purchases!$A$2:$A1000, purchases!$E$2:$E1000=A7))"),82.0) -> 82 | C7: {=XLOOKUP(A7, purchases!$E$2:$E1000, purchases!$F$2:$F1000)} -> 45323
A8: 45334 | B8: =IFERROR(__xludf.DUMMYFUNCTION("COUNTUNIQUE(FILTER(purchases!$A$2:$A1000, purchases!$E$2:$E1000=A8))"),72.0) -> 72 | C8: {=XLOOKUP(A8, purchases!$E$2:$E1000, purchases!$F$2:$F1000)} -> 45323
A9: 45341 | B9: =IFERROR(__xludf.DUMMYFUNCTION("COUNTUNIQUE(FILTER(purchases!$A$2:$A1000, purchases!$E$2:$E1000=A9))"),72.0) -> 72 | C9: {=XLOOKUP(A9, purchases!$E$2:$E1000, purchases!$F$2:$F1000)} -> 45323
A10: 45348 | B10: =IFERROR(__xludf.DUMMYFUNCTION("COUNTUNIQUE(FILTER(purchases!$A$2:$A1000, purchases!$E$2:$E1000=A10))"),77.0) -> 77 | C10: {=XLOOKUP(A10, purchases!$E$2:$E1000, purchases!$F$2:$F1000)} -> 45323
A11: 45355 | B11: =IFERROR(__xludf.DUMMYFUNCTION("COUNTUNIQUE(FILTER(purchases!$A$2:$A1000, purchases!$E$2:$E1000=A11))"),80.0) -> 80 | C11: {=XLOOKUP(A11, purchases!$E$2:$E1000, purchases!$F$2:$F1000)} -> 45352
A12: 45362 | B12: =IFERROR(__xludf.DUMMYFUNCTION("COUNTUNIQUE(FILTER(purchases!$A$2:$A1000, purchases!$E$2:$E1000=A12))"),82.0) -> 82 | C12: {=XLOOKUP(A12, purchases!$E$2:$E1000, purchases!$F$2:$F1000)} -> 45352
A13: 45369 | B13: =IFERROR(__xludf.DUMMYFUNCTION("COUNTUNIQUE(FILTER(purchases!$A$2:$A1000, purchases!$E$2:$E1000=A13))"),94.0) -> 94 | C13: {=XLOOKUP(A13, purchases!$E$2:$E1000, purchases!$F$2:$F1000)} -> 45352
A14: 45376 | B14: =IFERROR(__xludf.DUMMYFUNCTION("COUNTUNIQUE(FILTER(purchases!$A$2:$A1000, purchases!$E$2:$E1000=A14))"),90.0) -> 90 | C14: {=XLOOKUP(A14, purchases!$E$2:$E1000, purchases!$F$2:$F1000)} -> 45352
A15: 45383 | B15: =IFERROR(__xludf.DUMMYFUNCTION("COUNTUNIQUE(FILTER(purchases!$A$2:$A1000, purchases!$E$2:$E1000=A15))"),71.0) -> 71 | C15: {=XLOOKUP(A15, purchases!$E$2:$E1000, purchases!$F$2:$F1000)} -> 45383
A16: 45390 | B16: =IFERROR(__xludf.DUMMYFUNCTION("COUNTUNIQUE(FILTER(purchases!$A$2:$A1000, purchases!$E$2:$E1000=A16))"),72.0) -> 72 | C16: {=XLOOKUP(A16, purchases!$E$2:$E1000, purchases!$F$2:$F1000)} -> 45383
A17: 45397 | B17: =IFERROR(__xludf.DUMMYFUNCTION("COUNTUNIQUE(FILTER(purchases!$A$2:$A1000, purchases!$E$2:$E1000=A17))"),81.0) -> 81 | C17: {=XLOOKUP(A17, purchases!$E$2:$E1000, purchases!$F$2:$F1000)} -> 45383
A18: 45404 | B18: =IFERROR(__xludf.DUMMYFUNCTION("COUNTUNIQUE(FILTER(purchases!$A$2:$A1000, purchases!$E$2:$E1000=A18))"),74.0) -> 74 | C18: {=XLOOKUP(A18, purchases!$E$2:$E1000, purchases!$F$2:$F1000)} -> 45383
A19: 45411 | B19: =IFERROR(__xludf.DUMMYFUNCTION("COUNTUNIQUE(FILTER(purchases!$A$2:$A1000, purchases!$E$2:$E1000=A19))"),68.0) -> 68 | C19: {=XLOOKUP(A19, purchases!$E$2:$E1000, purchases!$F$2:$F1000)} -> 45383
A20: 45418 | B20: =IFERROR(__xludf.DUMMYFUNCTION("COUNTUNIQUE(FILTER(purchases!$A$2:$A1000, purchases!$E$2:$E1000=A20))"),69.0) -> 69 | C20: {=XLOOKUP(A20, purchases!$E$2:$E1000, purchases!$F$2:$F1000)} -> 45413
A21: 45425 | B21: =IFERROR(__xludf.DUMMYFUNCTION("COUNTUNIQUE(FILTER(purchases!$A$2:$A1000, purchases!$E$2:$E1000=A21))"),74.0) -> 74 | C21: {=XLOOKUP(A21, purchases!$E$2:$E1000, purchases!$F$2:$F1000)} -> 45413
A22: 45432 | B22: =IFERROR(__xludf.DUMMYFUNCTION("COUNTUNIQUE(FILTER(purchases!$A$2:$A1000, purchases!$E$2:$E1000=A22))"),76.0) -> 76 | C22: {=XLOOKUP(A22, purchases!$E$2:$E1000, purchases!$F$2:$F1000)} -> 45413
A23: 45439 | B23: =IFERROR(__xludf.DUMMYFUNCTION("COUNTUNIQUE(FILTER(purchases!$A$2:$A1000, purchases!$E$2:$E1000=A23))"),70.0) -> 70 | C23: {=XLOOKUP(A23, purchases!$E$2:$E1000, purchases!$F$2:$F1000)} -> 45413
A24: 45446 | B24: =IFERROR(__xludf.DUMMYFUNCTION("COUNTUNIQUE(FILTER(purchases!$A$2:$A1000, purchases!$E$2:$E1000=A24))"),71.0) -> 71 | C24: {=XLOOKUP(A24, purchases!$E$2:$E1000, purchases!$F$2:$F1000)} -> 45444
A25: 45453 | B25: =IFERROR(__xludf.DUMMYFUNCTION("COUNTUNIQUE(FILTER(purchases!$A$2:$A1000, purchases!$E$2:$E1000=A25))"),79.0) -> 79 | C25: {=XLOOKUP(A25, purchases!$E$2:$E1000, purchases!$F$2:$F1000)} -> 45444
A26: 45460 | B26: =IFERROR(__xludf.DUMMYFUNCTION("COUNTUNIQUE(FILTER(purchases!$A$2:$A1000, purchases!$E$2:$E1000=A26))"),63.0) -> 63 | C26: {=XLOOKUP(A26, purchases!$E$2:$E1000, purchases!$F$2:$F1000)} -> 45444
A27: 45467 | B27: =IFERROR(__xludf.DUMMYFUNCTION("COUNTUNIQUE(FILTER(purchases!$A$2:$A1000, purchases!$E$2:$E1000=A27))"),71.0) -> 71 | C27: {=XLOOKUP(A27, purchases!$E$2:$E1000, purchases!$F$2:$F1000)} -> 45444
A28: 45474 | B28: =IFERROR(__xludf.DUMMYFUNCTION("COUNTUNIQUE(FILTER(purchases!$A$2:$A1000, purchases!$E$2:$E1000=A28))"),67.0) -> 67 | C28: {=XLOOKUP(A28, purchases!$E$2:$E1000, purchases!$F$2:$F1000)} -> 45474
A29: 45481 | B29: =IFERROR(__xludf.DUMMYFUNCTION("COUNTUNIQUE(FILTER(purchases!$A$2:$A1000, purchases!$E$2:$E1000=A29))"),3.0) -> 3 | C29: {=XLOOKUP(A29, purchases!$E$2:$E1000, purchases!$F$2:$F1000)} -> 45474

Sheet mau
A1: Month | B1: MAU | C1: Average DAU | D1: Average WAU | E1: DAU/MAU | F1: WAU/MAU
A2: {=SORT(UNIQUE(purchases!F2:F1000))} -> 45292 | B2: =IFERROR(__xludf.DUMMYFUNCTION("COUNTUNIQUE(FILTER(purchases!$A$2:$A1000, purchases!$F$2:$F1000=A2))"),295.0) -> 295 | C2: =ROUND(AVERAGEIF(dau!$C$2:$C1000, A2, dau!$B$2:$B1000), 2) -> 9.83 | D2: =ROUND(AVERAGEIF(wau!$C$2:$C1000, A2, wau!$B$2:$B1000), 2) -> 68.4 | E2: =ROUND(C2/B2, 2) -> 0.03 | F2: =ROUND(D2/B2, 2) -> 0.23
A3: 45323 | B3: =IFERROR(__xludf.DUMMYFUNCTION("COUNTUNIQUE(FILTER(purchases!$A$2:$A1000, purchases!$F$2:$F1000=A3))"),319.0) -> 319 | C3: =ROUND(AVERAGEIF(dau!$C$2:$C1000, A3, dau!$B$2:$B1000), 2) -> 11 | D3: =ROUND(AVERAGEIF(wau!$C$2:$C1000, A3, wau!$B$2:$B1000), 2) -> 75.75 | E3: =ROUND(C3/B3, 2) -> 0.03 | F3: =ROUND(D3/B3, 2) -> 0.24
A4: 45352 | B4: =IFERROR(__xludf.DUMMYFUNCTION("COUNTUNIQUE(FILTER(purchases!$A$2:$A1000, purchases!$F$2:$F1000=A4))"),377.0) -> 377 | C4: =ROUND(AVERAGEIF(dau!$C$2:$C1000, A4, dau!$B$2:$B1000), 2) -> 12.16 | D4: =ROUND(AVERAGEIF(wau!$C$2:$C1000, A4, wau!$B$2:$B1000), 2) -> 86.5 | E4: =ROUND(C4/B4, 2) -> 0.03 | F4: =ROUND(D4/B4, 2) -> 0.23
A5: 45383 | B5: =IFERROR(__xludf.DUMMYFUNCTION("COUNTUNIQUE(FILTER(purchases!$A$2:$A1000, purchases!$F$2:$F1000=A5))"),318.0) -> 318 | C5: =ROUND(AVERAGEIF(dau!$C$2:$C1000, A5, dau!$B$2:$B1000), 2) -> 10.6 | D5: =ROUND(AVERAGEIF(wau!$C$2:$C1000, A5, wau!$B$2:$B1000), 2) -> 73.2 | E5: =ROUND(C5/B5, 2) -> 0.03 | F5: =ROUND(D5/B5, 2) -> 0.23
A6: 45413 | B6: =IFERROR(__xludf.DUMMYFUNCTION("COUNTUNIQUE(FILTER(purchases!$A$2:$A1000, purchases!$F$2:$F1000=A6))"),316.0) -> 316 | C6: =ROUND(AVERAGEIF(dau!$C$2:$C1000, A6, dau!$B$2:$B1000), 2) -> 10.19 | D6: =ROUND(AVERAGEIF(wau!$C$2:$C1000, A6, wau!$B$2:$B1000), 2) -> 72.25 | E6: =ROUND(C6/B6, 2) -> 0.03 | F6: =ROUND(D6/B6, 2) -> 0.23
A7: 45444 | B7: =IFERROR(__xludf.DUMMYFUNCTION("COUNTUNIQUE(FILTER(purchases!$A$2:$A1000, purchases!$F$2:$F1000=A7))"),305.0) -> 305 | C7: =ROUND(AVERAGEIF(dau!$C$2:$C1000, A7, dau!$B$2:$B1000), 2) -> 10.17 | D7: =ROUND(AVERAGEIF(wau!$C$2:$C1000, A7, wau!$B$2:$B1000), 2) -> 71 | E7: =ROUND(C7/B7, 2) -> 0.03 | F7: =ROUND(D7/B7, 2) -> 0.23
A8: 45474 | B8: =IFERROR(__xludf.DUMMYFUNCTION("COUNTUNIQUE(FILTER(purchases!$A$2:$A1000, purchases!$F$2:$F1000=A8))"),70.0) -> 70 | C8: =ROUND(AVERAGEIF(dau!$C$2:$C1000, A8, dau!$B$2:$B1000), 2) -> 8.75 | D8: =ROUND(AVERAGEIF(wau!$C$2:$C1000, A8, wau!$B$2:$B1000), 2) -> 35 | E8: =ROUND(C8/B8, 2) -> 0.13 | F8: =ROUND(D8/B8, 2) -> 0.5

Sheet key insights
A1: Metric | B1: Key Insight
A2: MAU peak | B2: Highest in March
A3: DAU trend | B3: Stable over time
A4: WAU trend | B4: Slight decline
A5: Stickiness | B5: Low daily engagement
